2024-08-09 04:58:17,471 INFO    StreamThr :3146678 [internal.py:wandb_internal():85] W&B internal server running at pid: 3146678, started at: 2024-08-09 04:58:17.470308
2024-08-09 04:58:17,478 DEBUG   HandlerThread:3146678 [handler.py:handle_request():158] handle_request: status
2024-08-09 04:58:17,479 INFO    WriterThread:3146678 [datastore.py:open_for_write():87] open: /scratch/gpfs/vs3041/cruijff/llama-recipes-fertility/recipes/quickstart/wandb/run-20240809_045817-synfj0by/run-synfj0by.wandb
2024-08-09 04:58:17,480 DEBUG   SenderThread:3146678 [sender.py:send():379] send: header
2024-08-09 04:58:17,481 DEBUG   SenderThread:3146678 [sender.py:send():379] send: run
2024-08-09 04:58:21,151 INFO    SenderThread:3146678 [retry.py:__call__():172] Retry attempt failed:
Traceback (most recent call last):
  File "/home/vs3041/.cruijff/lib/python3.11/site-packages/urllib3/connection.py", line 196, in _new_conn
    sock = connection.create_connection(
           ^^^^^^^^^^^^^^^^^^^^^^^^^^^^^
  File "/home/vs3041/.cruijff/lib/python3.11/site-packages/urllib3/util/connection.py", line 60, in create_connection
    for res in socket.getaddrinfo(host, port, family, socket.SOCK_STREAM):
               ^^^^^^^^^^^^^^^^^^^^^^^^^^^^^^^^^^^^^^^^^^^^^^^^^^^^^^^^^^
  File "/usr/licensed/anaconda3/2024.2/lib/python3.11/socket.py", line 962, in getaddrinfo
    for res in _socket.getaddrinfo(host, port, family, type, proto, flags):
               ^^^^^^^^^^^^^^^^^^^^^^^^^^^^^^^^^^^^^^^^^^^^^^^^^^^^^^^^^^^
socket.gaierror: [Errno -2] Name or service not known

The above exception was the direct cause of the following exception:

Traceback (most recent call last):
  File "/home/vs3041/.cruijff/lib/python3.11/site-packages/urllib3/connectionpool.py", line 789, in urlopen
    response = self._make_request(
               ^^^^^^^^^^^^^^^^^^^
  File "/home/vs3041/.cruijff/lib/python3.11/site-packages/urllib3/connectionpool.py", line 490, in _make_request
    raise new_e
  File "/home/vs3041/.cruijff/lib/python3.11/site-packages/urllib3/connectionpool.py", line 466, in _make_request
    self._validate_conn(conn)
  File "/home/vs3041/.cruijff/lib/python3.11/site-packages/urllib3/connectionpool.py", line 1095, in _validate_conn
    conn.connect()
  File "/home/vs3041/.cruijff/lib/python3.11/site-packages/urllib3/connection.py", line 615, in connect
    self.sock = sock = self._new_conn()
                       ^^^^^^^^^^^^^^^^
  File "/home/vs3041/.cruijff/lib/python3.11/site-packages/urllib3/connection.py", line 203, in _new_conn
    raise NameResolutionError(self.host, self, e) from e
urllib3.exceptions.NameResolutionError: <urllib3.connection.HTTPSConnection object at 0x14c51365a750>: Failed to resolve 'api.wandb.ai' ([Errno -2] Name or service not known)

The above exception was the direct cause of the following exception:

Traceback (most recent call last):
  File "/home/vs3041/.cruijff/lib/python3.11/site-packages/requests/adapters.py", line 667, in send
    resp = conn.urlopen(
           ^^^^^^^^^^^^^
  File "/home/vs3041/.cruijff/lib/python3.11/site-packages/urllib3/connectionpool.py", line 843, in urlopen
    retries = retries.increment(
              ^^^^^^^^^^^^^^^^^^
  File "/home/vs3041/.cruijff/lib/python3.11/site-packages/urllib3/util/retry.py", line 519, in increment
    raise MaxRetryError(_pool, url, reason) from reason  # type: ignore[arg-type]
    ^^^^^^^^^^^^^^^^^^^^^^^^^^^^^^^^^^^^^^^^^^^^^^^^^^^
urllib3.exceptions.MaxRetryError: HTTPSConnectionPool(host='api.wandb.ai', port=443): Max retries exceeded with url: /graphql (Caused by NameResolutionError("<urllib3.connection.HTTPSConnection object at 0x14c51365a750>: Failed to resolve 'api.wandb.ai' ([Errno -2] Name or service not known)"))

During handling of the above exception, another exception occurred:

Traceback (most recent call last):
  File "/home/vs3041/.cruijff/lib/python3.11/site-packages/wandb/sdk/lib/retry.py", line 131, in __call__
    result = self._call_fn(*args, **kwargs)
             ^^^^^^^^^^^^^^^^^^^^^^^^^^^^^^
  File "/home/vs3041/.cruijff/lib/python3.11/site-packages/wandb/sdk/internal/internal_api.py", line 345, in execute
    return self.client.execute(*args, **kwargs)  # type: ignore
           ^^^^^^^^^^^^^^^^^^^^^^^^^^^^^^^^^^^^
  File "/home/vs3041/.cruijff/lib/python3.11/site-packages/wandb/vendor/gql-0.2.0/wandb_gql/client.py", line 52, in execute
    result = self._get_result(document, *args, **kwargs)
             ^^^^^^^^^^^^^^^^^^^^^^^^^^^^^^^^^^^^^^^^^^^
  File "/home/vs3041/.cruijff/lib/python3.11/site-packages/wandb/vendor/gql-0.2.0/wandb_gql/client.py", line 60, in _get_result
    return self.transport.execute(document, *args, **kwargs)
           ^^^^^^^^^^^^^^^^^^^^^^^^^^^^^^^^^^^^^^^^^^^^^^^^^
  File "/home/vs3041/.cruijff/lib/python3.11/site-packages/wandb/sdk/lib/gql_request.py", line 58, in execute
    request = self.session.post(self.url, **post_args)
              ^^^^^^^^^^^^^^^^^^^^^^^^^^^^^^^^^^^^^^^^
  File "/home/vs3041/.cruijff/lib/python3.11/site-packages/requests/sessions.py", line 637, in post
    return self.request("POST", url, data=data, json=json, **kwargs)
           ^^^^^^^^^^^^^^^^^^^^^^^^^^^^^^^^^^^^^^^^^^^^^^^^^^^^^^^^^
  File "/home/vs3041/.cruijff/lib/python3.11/site-packages/requests/sessions.py", line 589, in request
    resp = self.send(prep, **send_kwargs)
           ^^^^^^^^^^^^^^^^^^^^^^^^^^^^^^
  File "/home/vs3041/.cruijff/lib/python3.11/site-packages/requests/sessions.py", line 703, in send
    r = adapter.send(request, **kwargs)
        ^^^^^^^^^^^^^^^^^^^^^^^^^^^^^^^
  File "/home/vs3041/.cruijff/lib/python3.11/site-packages/requests/adapters.py", line 700, in send
    raise ConnectionError(e, request=request)
requests.exceptions.ConnectionError: HTTPSConnectionPool(host='api.wandb.ai', port=443): Max retries exceeded with url: /graphql (Caused by NameResolutionError("<urllib3.connection.HTTPSConnection object at 0x14c51365a750>: Failed to resolve 'api.wandb.ai' ([Errno -2] Name or service not known)"))
2024-08-09 04:58:22,481 DEBUG   HandlerThread:3146678 [handler.py:handle_request():158] handle_request: keepalive
2024-08-09 04:58:27,482 DEBUG   HandlerThread:3146678 [handler.py:handle_request():158] handle_request: keepalive
2024-08-09 04:58:32,482 DEBUG   HandlerThread:3146678 [handler.py:handle_request():158] handle_request: keepalive
2024-08-09 04:58:37,483 DEBUG   HandlerThread:3146678 [handler.py:handle_request():158] handle_request: keepalive
2024-08-09 04:58:42,483 DEBUG   HandlerThread:3146678 [handler.py:handle_request():158] handle_request: keepalive
2024-08-09 04:58:47,483 DEBUG   HandlerThread:3146678 [handler.py:handle_request():158] handle_request: keepalive
2024-08-09 04:58:52,484 DEBUG   HandlerThread:3146678 [handler.py:handle_request():158] handle_request: keepalive
2024-08-09 04:58:57,485 DEBUG   HandlerThread:3146678 [handler.py:handle_request():158] handle_request: keepalive
2024-08-09 04:59:02,485 DEBUG   HandlerThread:3146678 [handler.py:handle_request():158] handle_request: keepalive
2024-08-09 04:59:07,486 DEBUG   HandlerThread:3146678 [handler.py:handle_request():158] handle_request: keepalive
2024-08-09 04:59:12,486 DEBUG   HandlerThread:3146678 [handler.py:handle_request():158] handle_request: keepalive
2024-08-09 04:59:17,487 DEBUG   HandlerThread:3146678 [handler.py:handle_request():158] handle_request: keepalive
2024-08-09 04:59:22,487 DEBUG   HandlerThread:3146678 [handler.py:handle_request():158] handle_request: keepalive
2024-08-09 04:59:27,488 DEBUG   HandlerThread:3146678 [handler.py:handle_request():158] handle_request: keepalive
2024-08-09 04:59:32,488 DEBUG   HandlerThread:3146678 [handler.py:handle_request():158] handle_request: keepalive
2024-08-09 04:59:37,489 DEBUG   HandlerThread:3146678 [handler.py:handle_request():158] handle_request: keepalive
2024-08-09 04:59:42,490 DEBUG   HandlerThread:3146678 [handler.py:handle_request():158] handle_request: keepalive
2024-08-09 04:59:47,491 DEBUG   HandlerThread:3146678 [handler.py:handle_request():158] handle_request: cancel
2024-08-09 04:59:47,491 DEBUG   HandlerThread:3146678 [handler.py:handle_request():158] handle_request: cancel
2024-08-09 04:59:47,491 DEBUG   SenderThread:3146678 [sender.py:send():388] Record cancelled: run
2024-08-09 04:59:47,491 DEBUG   HandlerThread:3146678 [handler.py:handle_request():158] handle_request: status_report
2024-08-09 04:59:47,515 DEBUG   HandlerThread:3146678 [handler.py:handle_request():158] handle_request: shutdown
2024-08-09 04:59:47,515 INFO    HandlerThread:3146678 [handler.py:finish():882] shutting down handler
2024-08-09 04:59:48,491 INFO    SenderThread:3146678 [sender.py:finish():1615] shutting down sender
2024-08-09 04:59:48,491 INFO    WriterThread:3146678 [datastore.py:close():296] close: /scratch/gpfs/vs3041/cruijff/llama-recipes-fertility/recipes/quickstart/wandb/run-20240809_045817-synfj0by/run-synfj0by.wandb
